<?xml version="1.0" ?>

<robot name="spot" xmlns:xacro="http://www.ros.org/wiki/xacro">

  <!--======================================================================-->
  <!-- Dummy link -->
  <link name="body">
     <visual>
       <origin rpy="0 0 0" xyz="0 0 0"/>
       <geometry>
         <box size="0.001 0.001 0.001"/>
       </geometry>
     </visual>
   </link>
  
  <joint name="floating_base" type="fixed">
      <origin rpy="0 0 0" xyz="0 0 0"/>
      <parent link="body"/>
      <child link="trunk"/>
    </joint>
  <!--======================================================================-->

  <link name="trunk">
    <visual>
      <origin rpy="0 0 0" xyz="0 0 0"/>
      <geometry>
		  <mesh filename="package://spot_description/meshes/body.dae" scale="1 1 1"/>
      </geometry>
    </visual>
    <collision>
      <origin rpy="0 0 0" xyz="0 0 0.01675"/>
      <geometry>
        <box size="0.78 0.25 0.21"/>
      </geometry>
    </collision>
    <inertial>
      <origin rpy="0 0 0" xyz="0.002284 -4.1e-05 0.025165"/>
      <mass value="13.733"/>
      <inertia ixx="0.073348887" ixy="0.00030338" ixz="0.001918218" iyy="0.250684593" iyz="-7.5402e-05" izz="0.254469458"/>
    </inertial>
  </link>
  
  <!--======================================================================-->

  <joint name="imu_joint" type="fixed">
      <parent link="trunk"/>
      <child link="imu_link"/>
      <origin rpy="0 0 0" xyz="0 0 0"/>
  </joint>

  <link name="imu_link">
      <inertial>
        <mass value="0.001"/>
        <origin rpy="0 0 0" xyz="0 0 0"/>
        <inertia ixx="0.0001" ixy="0" ixz="0" iyy="0.0001" iyz="0" izz="0.0001"/>
      </inertial>
      <visual>
        <origin rpy="0 0 0" xyz="0 0 0"/>
        <geometry>
          <box size="0.001 0.001 0.001"/>
        </geometry>
      </visual>
      <collision>
        <origin rpy="0 0 0" xyz="0 0 0"/>
        <geometry>
          <box size=".001 .001 .001"/>
        </geometry>
      </collision>
  </link>

  <!--======================================================================-->

  <joint name="camera_joint" type="fixed">
      <parent link="trunk"/>
      <child link="camera_link"/>
      <origin rpy="0 0 0" xyz="0.42 0 0"/>
  </joint>

  <link name="camera_link"/>

  <joint name="camera_optical_joint" type="fixed">
    <origin xyz="0 0 0" rpy="-1.57 0 -1.57"/>
    <parent link="camera_link"/>
    <child link="camera_optical"/>
  </joint>

  <link name="camera_optical"/>

  <!--======================================================================-->
  
  <!-- Front right leg -->
  <joint name="10" type="revolute">
    <origin rpy="0 0 0" xyz="0.29785 -0.055 0"/>
    <parent link="trunk"/>
    <child link="hip2"/>
    <axis xyz="1 0 0"/>
    <dynamics damping="0" friction="0"/>
    <limit effort="20" lower="-3.14" upper="3.14" velocity="52.4"/>
  </joint>

  <link name="hip2">
    <visual>
      <origin rpy="0 0 0" xyz="0 0 0"/>
      <geometry>
		  <mesh filename="package://spot_description/meshes/front_right_hip.dae" scale="1 1 1"/>
      </geometry>
    </visual>
    <collision>
      <origin rpy="1.57079632679 0 0" xyz="0 0.021 0"/>
      <geometry>
        <cylinder length="0.08" radius="0.041"/>
      </geometry>
    </collision>
    <inertial>
      <origin rpy="0 0 0" xyz="-0.001568 0.008134 0.000864"/>
      <mass value="1.096"/>
      <inertia ixx="0.000822113" ixy="4.982e-06" ixz="-3.672e-05" iyy="0.000983196" iyz="-2.811e-06" izz="0.000864753"/>
    </inertial>
  </link>

  <joint name="4" type="revolute">
    <origin rpy="0 0 0" xyz="0 -0.11095 0"/>
    <parent link="hip2"/>
    <child link="upper2"/>
    <axis xyz="0 -1 0"/>
    <dynamics damping="0" friction="0"/>
    <limit effort="55" lower="-3.14" upper="3.14" velocity="28.6"/>
  </joint>
  
  <link name="upper2">
    <visual>
      <origin rpy="0 0.075 0" xyz="0 0 0"/>
      <geometry>
		  <mesh filename="package://spot_description/meshes/front_right_upper_leg.dae" scale="1 1 1"/>
      </geometry>
    </visual>
    <collision>
      <origin rpy="0 1.57 0" xyz="0 0 -0.16"/>
      <geometry>
        <box size="0.32 0.034 0.043"/>
      </geometry>
    </collision>
    <inertial>
      <origin rpy="0 0 0" xyz="-0.000482 -0.02001 -0.031996"/>
      <mass value="0.228"/>
      <inertia ixx="0.0099611" ixy="-1.0388e-05" ixz="0.000250428" iyy="0.009280083" iyz="8.511e-05" izz="0.00178256"/>
    </inertial>
  </link>
  
  <joint name="5" type="revolute">
    <origin rpy="0 0 0" xyz="0 0 -0.32147"/>
    <parent link="upper2"/>
    <child link="lower2"/>
    <axis xyz="0 1 0"/>
    <dynamics damping="0" friction="0"/>
    <limit effort="55" lower="-3.14" upper="3.14" velocity="28.6"/>
  </joint>
  
  <link name="lower2">
    <visual>
      <origin rpy="0 0 0" xyz="0 0 0"/>
      <geometry>
		  <mesh filename="package://spot_description/meshes/front_right_lower_leg.dae" scale="1 1 1"/>
      </geometry>
    </visual>
    <collision>
      <origin rpy="0 1.57 0" xyz="0 0 -0.165"/>
      <geometry>
        <box size="0.33 0.016 0.016"/>
      </geometry>
    </collision>
    <inertial>
      <origin rpy="0 0 0" xyz="-0.002196 -0.000381 -0.12338"/>
      <mass value="0.041"/>
      <inertia ixx="0.006181961" ixy="2.37e-07" ixz="-2.985e-06" iyy="0.006196546" iyz="5.138e-06" izz="3.4774e-05"/>
    </inertial>
  </link>

  <joint name="jtoe2" type="fixed">
    <origin rpy="0 0 0" xyz="0 0 -0.333"/>
    <parent link="lower2"/>
    <child link="toe2"/>
  </joint>
  
  <link name="toe2">
    <collision name="toe2_collision">
      <origin rpy="0 0 0" xyz="0 0 0"/>
      <geometry>
        <sphere radius="0.037"/>
      </geometry>
      <surface>
        <bounce>
          <restitution_coefficient>0</restitution_coefficient>
          <threshold>1e+06</threshold>
        </bounce>
        <friction>
          <ode>
            <mu>0.5</mu>
            <mu2>0.5</mu2>
          </ode>
          <bullet>
            <rolling_friction>0.3</rolling_friction>
            <friction2>50</friction2>
          </bullet>
        </friction>
        <contact>
          <ode>
            <kp>30000.0</kp>
            <kd>1000.0</kd>
          </ode>
          <bullet>
            <kp>30000.0</kp>
            <kd>1000.0</kd>
            <split_impulse>1</split_impulse>
            <split_impulse_penetration_threshold>-0.01</split_impulse_penetration_threshold>
          </bullet>
        </contact>
      </surface>
    </collision>
    <inertial>
      <mass value="0.01"/>
      <inertia ixx="1.6854e-05" ixy="0.0" ixz="0.0" iyy="1.6854e-05" iyz="0.0" izz="1.6854e-05"/>
    </inertial>
  </link>
  
  <!--======================================================================-->
  
  <!-- Front left leg -->
  <joint name="8" type="revolute">
    <origin rpy="0 0 0" xyz="0.29785 0.055 0"/>
    <parent link="trunk"/>
    <child link="hip0"/>
    <axis xyz="1 0 0"/>
    <dynamics damping="0" friction="0"/>
    <limit effort="20" lower="-3.14" upper="3.14" velocity="52.4"/>
  </joint>

  <link name="hip0">
    <visual>
      <origin rpy="0 0 0" xyz="0 0 0"/>
      <geometry>
		  <mesh filename="package://spot_description/meshes/front_left_hip.dae" scale="1 1 1"/>
      </geometry>
    </visual>
    <collision>
      <origin rpy="1.57079632679 0 0" xyz="0 -0.021 0"/>
      <geometry>
        <cylinder length="0.08" radius="0.041"/>
      </geometry>
    </collision>
    <inertial>
      <origin rpy="0 0 0" xyz="-0.001568 -0.008134 0.000864"/>
      <mass value="1.096"/>
      <inertia ixx="0.000822113" ixy="-4.982e-06" ixz="-3.672e-05" iyy="0.000983196" iyz="2.811e-06" izz="0.000864753"/>
    </inertial>
  </link>
  
  <joint name="0" type="revolute">
    <origin rpy="0 0 0" xyz="0 0.11095 0"/>
    <parent link="hip0"/>
    <child link="upper0"/>
    <axis xyz="0 -1 0"/>
    <dynamics damping="0" friction="0"/>
    <limit effort="55" lower="-3.14" upper="3.14" velocity="28.6"/>
  </joint>
  
  <link name="upper0">
    <visual>
      <origin rpy="0 0.075 0" xyz="0 0 0"/>
      <geometry>
		  <mesh filename="package://spot_description/meshes/front_left_upper_leg.dae" scale="1 1 1"/>
      </geometry>
    </visual>
    <collision>
      <origin rpy="0 -1.57 0" xyz="0 0 -0.16"/>
      <geometry>
        <box size="0.32 0.034 0.043"/>
      </geometry>
    </collision>
    <inertial>
      <origin rpy="0 0 0" xyz="-0.000482 0.02001 -0.031996"/>
      <mass value="0.228"/>
      <inertia ixx="0.00991611" ixy="1.0388e-05" ixz="0.000250428" iyy="0.009280083" iyz="-8.511e-05" izz="0.00178256"/>
    </inertial>
  </link>
	  
  <joint name="1" type="revolute">
    <origin rpy="0 0 0" xyz="0 0 -0.32147"/>
    <parent link="upper0"/>
    <child link="lower0"/>
    <axis xyz="0 1 0"/>
    <dynamics damping="0" friction="0"/>
    <limit effort="55" lower="-3.14" upper="3.14" velocity="28.6"/>
  </joint>
  
  <link name="lower0">
    <visual>
      <origin rpy="0 0 0" xyz="0 0 0"/>
      <geometry>
		  <mesh filename="package://spot_description/meshes/front_left_lower_leg.dae" scale="1 1 1"/>
      </geometry>
    </visual>
    <collision>
      <origin rpy="0 1.57 0" xyz="0 0 -0.165"/>
      <geometry>
        <box size="0.33 0.016 0.016"/>
      </geometry>
    </collision>
    <inertial>
      <origin rpy="0 0 0" xyz="-0.002196 -0.000381 -0.12338"/>
      <mass value="0.041"/>
      <inertia ixx="0.006181961" ixy="2.37e-07" ixz="-2.985e-06" iyy="0.006196546" iyz="5.138e-06" izz="3.4774e-05"/>
    </inertial>
  </link>

  <joint name="jtoe0" type="fixed">
    <origin rpy="0 0 0" xyz="0 0 -0.333"/>
    <parent link="lower0"/>
    <child link="toe0"/>
  </joint>
  
  <link name="toe0">
    <collision name="toe0_collision">
      <origin rpy="0 0 0" xyz="0 0 0"/>
      <geometry>
        <sphere radius="0.037"/>
      </geometry>
      <surface>
        <bounce>
          <restitution_coefficient>0</restitution_coefficient>
          <threshold>1e+06</threshold>
        </bounce>
        <friction>
          <ode>
            <mu>0.5</mu>
            <mu2>0.5</mu2>
          </ode>
          <bullet>
            <rolling_friction>0.3</rolling_friction>
            <friction2>50</friction2>
          </bullet>
        </friction>
        <contact>
          <ode>
            <kp>30000.0</kp>
            <kd>1000.0</kd>
          </ode>
          <bullet>
            <kp>30000.0</kp>
            <kd>1000.0</kd>
            <split_impulse>1</split_impulse>
            <split_impulse_penetration_threshold>-0.01</split_impulse_penetration_threshold>
          </bullet>
        </contact>
      </surface>
    </collision>
    <inertial>
      <mass value="0.01"/>
      <inertia ixx="1.6854e-05" ixy="0.0" ixz="0.0" iyy="1.6854e-05" iyz="0.0" izz="1.6854e-05"/>
    </inertial>
  </link>

  <!--======================================================================-->
  
  <!-- Rear right leg -->
  <joint name="11" type="revolute">
    <origin rpy="0 0 0" xyz="-0.29785 -0.055 0"/>
    <parent link="trunk"/>
    <child link="hip3"/>
    <axis xyz="1 0 0"/>
    <dynamics damping="0" friction="0"/>
    <limit effort="20" lower="-3.14" upper="3.14" velocity="52.4"/>
  </joint>

  <link name="hip3">
    <visual>
      <origin rpy="0 0 0" xyz="0 0 0"/>
      <geometry>
		  <mesh filename="package://spot_description/meshes/rear_right_hip.dae" scale="1 1 1"/>
      </geometry>
    </visual>
    <collision>
      <origin rpy="1.57079632679 0 0" xyz="0 0.021 0"/>
      <geometry>
        <cylinder length="0.08" radius="0.041"/>
      </geometry>
    </collision>
    <inertial>
      <origin rpy="0 0 0" xyz="0.001568 0.008134 0.000864"/>
      <mass value="1.096"/>
      <inertia ixx="0.000822113" ixy="-4.982e-06" ixz="3.672e-05" iyy="0.000983196" iyz="-2.811e-06" izz="0.000864753"/>
    </inertial>
  </link>

  <joint name="6" type="revolute">
    <origin rpy="0 0 0" xyz="0 -0.11095 0"/>
    <parent link="hip3"/>
    <child link="upper3"/>
    <axis xyz="0 -1 0"/>
    <dynamics damping="0" friction="0"/>
    <limit effort="55" lower="-3.14" upper="3.14" velocity="28.6"/>
  </joint>
  
  <link name="upper3">
    <visual>
      <origin rpy="0 0.075 0" xyz="0 0 0"/>
      <geometry>
		  <mesh filename="package://spot_description/meshes/rear_right_upper_leg.dae" scale="1 1 1"/>
      </geometry>
    </visual>
    <collision>
      <origin rpy="0 1.57 0" xyz="0 0 -0.16"/>
      <geometry>
        <box size="0.32 0.034 0.043"/>
      </geometry>
    </collision>
    <inertial>
      <origin rpy="0 0 0" xyz="-0.000482 -0.02001 -0.031996"/>
      <mass value="0.228"/>
      <inertia ixx="0.00991611" ixy="-1.0388e-05" ixz="0.000250428" iyy="0.009280083" iyz="8.511e-05" izz="0.00178256"/>
    </inertial>
  </link>

  <joint name="7" type="revolute">
    <origin rpy="0 0 0" xyz="0 0 -0.32147"/>
    <parent link="upper3"/>
    <child link="lower3"/>
    <axis xyz="0 1 0"/>
    <dynamics damping="0" friction="0"/>
    <limit effort="55" lower="-3.14" upper="3.14" velocity="28.6"/>
  </joint>
  
  <link name="lower3">
    <visual>
      <origin rpy="0 0 0" xyz="0 0 0"/>
      <geometry>
		  <mesh filename="package://spot_description/meshes/rear_right_lower_leg.dae" scale="1 1 1"/>
      </geometry>
    </visual>
    <collision>
      <origin rpy="0 1.57 0" xyz="0 0 -0.165"/>
      <geometry>
        <box size="0.33 0.016 0.016"/>
      </geometry>
    </collision>
    <inertial>
      <origin rpy="0 0 0" xyz="-0.002196 -0.000381 -0.12338"/>
      <mass value="0.041"/>
      <inertia ixx="0.006181961" ixy="2.37e-07" ixz="-2.985e-06" iyy="0.006196546" iyz="5.138e-06" izz="3.4774e-05"/>
    </inertial>
  </link>

  <joint name="jtoe3" type="fixed">
    <origin rpy="0 0 0" xyz="0 0 -0.333"/>
    <parent link="lower3"/>
    <child link="toe3"/>
  </joint>
  
  <link name="toe3">
    <collision name="toe3_collision">
      <origin rpy="0 0 0" xyz="0 0 0"/>
      <geometry>
        <sphere radius="0.037"/>
      </geometry>
      <surface>
        <bounce>
          <restitution_coefficient>0</restitution_coefficient>
          <threshold>1e+06</threshold>
        </bounce>
        <friction>
          <ode>
            <mu>0.5</mu>
            <mu2>0.5</mu2>
          </ode>
          <bullet>
            <rolling_friction>0.3</rolling_friction>
            <friction2>50</friction2>
          </bullet>
        </friction>
        <contact>
          <ode>
            <kp>30000.0</kp>
            <kd>1000.0</kd>
          </ode>
          <bullet>
            <kp>30000.0</kp>
            <kd>1000.0</kd>
            <split_impulse>1</split_impulse>
            <split_impulse_penetration_threshold>-0.01</split_impulse_penetration_threshold>
          </bullet>
        </contact>
      </surface>
    </collision>
    <inertial>
      <mass value="0.01"/>
      <inertia ixx="1.6854e-05" ixy="0.0" ixz="0.0" iyy="1.6854e-05" iyz="0.0" izz="1.6854e-05"/>
    </inertial>
  </link>
  
  <!--======================================================================-->
  
  <!-- Rear left leg -->
  <joint name="9" type="revolute">
    <origin rpy="0 0 0" xyz="-0.29785 0.055 0"/>
    <parent link="trunk"/>
    <child link="hip1"/>
    <axis xyz="1 0 0"/>
    <dynamics damping="0" friction="0"/>
    <limit effort="20" lower="-3.14" upper="3.14" velocity="52.4"/>
  </joint>
  
  <link name="hip1">
    <visual>
      <origin rpy="0 0 0" xyz="0 0 0"/>
      <geometry>
		  <mesh filename="package://spot_description/meshes/rear_left_hip.dae" scale="1 1 1"/>
      </geometry>
    </visual>
    <collision>
      <origin rpy="1.57079632679 0 0" xyz="0 -0.021 0"/>
      <geometry>
        <cylinder length="0.08" radius="0.041"/>
      </geometry>
    </collision>
    <inertial>
      <origin rpy="0 0 0" xyz="0.001568 -0.008134 0.000864"/>
      <mass value="1.096"/>
      <inertia ixx="0.000822113" ixy="4.982e-06" ixz="3.672e-05" iyy="0.000983196" iyz="2.811e-06" izz="0.000864753"/>
    </inertial>
  </link>

  <joint name="2" type="revolute">
    <origin rpy="0 0 0" xyz="0 0.11095 0"/>
    <parent link="hip1"/>
    <child link="upper1"/>
    <axis xyz="0 -1 0"/>
    <dynamics damping="0" friction="0"/>
    <limit effort="55" lower="-3.14" upper="3.14" velocity="28.6"/>
  </joint>
  
  <link name="upper1">
    <visual>
      <origin rpy="0 0.075 0" xyz="0 0 0"/>
      <geometry>
		  <mesh filename="package://spot_description/meshes/rear_left_upper_leg.dae" scale="1 1 1"/>
      </geometry>
    </visual>
    <collision>
      <origin rpy="0 1.57 0" xyz="0 0 -0.16"/>
      <geometry>
        <box size="0.32 0.034 0.043"/>
      </geometry>
    </collision>
    <inertial>
      <origin rpy="0 0 0" xyz="-0.000482 0.02001 -0.031996"/>
      <mass value="0.228"/>
      <inertia ixx="0.00991611" ixy="1.0388e-05" ixz="0.000250428" iyy="0.009280083" iyz="-8.511e-05" izz="0.00178256"/>
    </inertial>
  </link>

  <joint name="3" type="revolute">
    <origin rpy="0 0 0" xyz="0 0 -0.32147"/>
    <parent link="upper1"/>
    <child link="lower1"/>
    <axis xyz="0 1 0"/>
    <dynamics damping="0" friction="0"/>
    <limit effort="55" lower="-3.14" upper="3.14" velocity="28.6"/>
  </joint>
  
  <link name="lower1">
    <visual>
      <origin rpy="0 0 0" xyz="0 0 0"/>
      <geometry>
		  <mesh filename="package://spot_description/meshes/rear_left_lower_leg.dae" scale="1 1 1"/>
      </geometry>
    </visual>
    <collision>
      <origin rpy="0 1.57 0" xyz="0 0 -0.165"/>
      <geometry>
        <box size="0.33 0.016 0.016"/>
      </geometry>
    </collision>
    <inertial>
      <origin rpy="0 0 0" xyz="-0.002196 -0.000381 -0.12338"/>
      <mass value="0.041"/>
      <inertia ixx="0.006181961" ixy="2.37e-07" ixz="-2.985e-06" iyy="0.006196546" iyz="5.138e-06" izz="3.4774e-05"/>
    </inertial>
  </link>

  <joint name="jtoe1" type="fixed">
    <origin rpy="0 0 0" xyz="0 0 -0.333"/>
    <parent link="lower1"/>
    <child link="toe1"/>
  </joint>
  
  <link name="toe1">
    <collision name="toe1_collision">
      <origin rpy="0 0 0" xyz="0 0 0"/>
      <geometry>
        <sphere radius="0.037"/>
      </geometry>
      <surface>
        <bounce>
          <restitution_coefficient>0</restitution_coefficient>
          <threshold>1e+06</threshold>
        </bounce>
        <friction>
          <ode>
            <mu>0.5</mu>
            <mu2>0.5</mu2>
          </ode>
          <bullet>
            <rolling_friction>0.3</rolling_friction>
            <friction2>50</friction2>
          </bullet>
        </friction>
        <contact>
          <ode>
            <kp>30000.0</kp>
            <kd>1000.0</kd>
          </ode>
          <bullet>
            <kp>30000.0</kp>
            <kd>1000.0</kd>
            <split_impulse>1</split_impulse>
            <split_impulse_penetration_threshold>-0.01</split_impulse_penetration_threshold>
          </bullet>
        </contact>
      </surface>
    </collision>
    <inertial>
      <mass value="0.01"/>
      <inertia ixx="1.6854e-05" ixy="0.0" ixz="0.0" iyy="1.6854e-05" iyz="0.0" izz="1.6854e-05"/>
    </inertial>
  </link>
  
  <!--======================================================================-->
  <!-- Gazebo plugins -->
  <gazebo>
  	<plugin filename="libgazebo_ros_control.so" name="gazebo_ros_control">
  	  <robotSimType>gazebo_ros_control/DefaultRobotHWSim</robotSimType>
  	</plugin>
  	<plugin filename="libground_truth_estimator.so" name="ground_truth_estimator">
  	  <updateRateHZ>500.0</updateRateHZ>
  	</plugin>
	<plugin filename="libgazebo_ros_force.so" name="gazebo_ros_force">
		  <bodyName>trunk</bodyName>
		  <topicName>/apply_force/trunk</topicName>
	</plugin>
  </gazebo>

  <gazebo reference="imu_link">
    <gravity>true</gravity>
    <sensor name="imu_sensor" type="imu">
      <always_on>true</always_on>
      <update_rate>500</update_rate>
      <visualize>true</visualize>
      <topic>__default_topic__</topic>
      <plugin filename="libgazebo_ros_imu_sensor.so" name="imu_plugin">
        <topicName>trunk_imu</topicName>
        <bodyName>imu_link</bodyName>
        <updateRateHZ>500.0</updateRateHZ>
        <gaussianNoise>0.0</gaussianNoise>
        <xyzOffset>0 0 0</xyzOffset>
        <rpyOffset>0 0 0</rpyOffset>
        <frameName>imu_link</frameName>
      </plugin>
      <pose>0 0 0 0 0 0</pose>
    </sensor>
  </gazebo>

  <gazebo reference="toe0">
    <sensor name="toe0_contact" type="contact">
      <plugin filename="libgazebo_ros_bumper.so" name="toe0_plugin">
        <alwaysOn>true</alwaysOn>
        <updateRate>500</updateRate>
        <bumperTopicName>gazebo/toe0_contact_state</bumperTopicName>
        <frameName>world</frameName>
      </plugin>
      <contact>
        <collision>toe0_collision</collision>
      </contact>
      <update_rate>500</update_rate>
    </sensor>
  </gazebo>

  <gazebo reference="toe1">
    <sensor name="toe1_contact" type="contact">
      <plugin filename="libgazebo_ros_bumper.so" name="toe1_plugin">
        <alwaysOn>true</alwaysOn>
        <updateRate>500</updateRate>
        <bumperTopicName>gazebo/toe1_contact_state</bumperTopicName>
        <frameName>world</frameName>
      </plugin>
      <contact>
        <collision>toe1_collision</collision>
      </contact>
      <update_rate>500</update_rate>
    </sensor>
  </gazebo>

  <gazebo reference="toe2">
    <sensor name="toe2_contact" type="contact">
      <plugin filename="libgazebo_ros_bumper.so" name="toe2_plugin">
        <alwaysOn>true</alwaysOn>
        <updateRate>500</updateRate>
        <bumperTopicName>gazebo/toe2_contact_state</bumperTopicName>
        <frameName>world</frameName>
      </plugin>
      <contact>
        <collision>toe2_collision</collision>
      </contact>
      <update_rate>500</update_rate>
    </sensor>
  </gazebo>

  <gazebo reference="toe3">
    <sensor name="toe3_contact" type="contact">
      <plugin filename="libgazebo_ros_bumper.so" name="toe3_plugin">
        <alwaysOn>true</alwaysOn>
        <updateRate>500</updateRate>
        <bumperTopicName>gazebo/toe3_contact_state</bumperTopicName>
        <frameName>world</frameName>
      </plugin>
      <contact>
        <collision>toe3_collision</collision>
      </contact>
      <update_rate>500</update_rate>
    </sensor>
  </gazebo>

  <!-- Material properties -->
  <gazebo reference="body">
    <turnGravityOff>false</turnGravityOff>
  </gazebo>
  <gazebo reference="trunk">
    <mu1>0.85</mu1>
    <mu2>0.85</mu2>
    <kp value="1000000.0"/>
    <kd value="1.0"/>
  </gazebo>

  <!-- Front left leg -->
  <gazebo reference="hip0">
    <mu1>0.85</mu1>
    <mu2>0.85</mu2>
  </gazebo>
  <gazebo reference="upper0">
    <mu1>0.85</mu1>
    <mu2>0.85</mu2>
    <self_collide>0</self_collide>
    <kp value="1000000.0"/>
    <kd value="1.0"/>
  </gazebo>
  <gazebo reference="lower0">
    <mu1>0.85</mu1>
    <mu2>0.85</mu2>
    <self_collide>0</self_collide>
  </gazebo>
  <gazebo reference="toe0">
    <mu1>0.85</mu1>
    <mu2>0.85</mu2>
    <self_collide>0</self_collide>
    <kp value="1000000.0"/>
    <kd value="1.0"/>
  </gazebo>
  
  <!-- Rear left leg -->
  <gazebo reference="hip1">
    <mu1>0.85</mu1>
    <mu2>0.85</mu2>
  </gazebo>
  <gazebo reference="upper1">
    <mu1>0.85</mu1>
    <mu2>0.85</mu2>
    <self_collide>0</self_collide>
    <kp value="1000000.0"/>
    <kd value="1.0"/>
  </gazebo>
  <gazebo reference="lower1">
    <mu1>0.85</mu1>
    <mu2>0.85</mu2>
    <self_collide>0</self_collide>
  </gazebo>
  <gazebo reference="toe1">
    <mu1>0.85</mu1>
    <mu2>0.85</mu2>
    <self_collide>0</self_collide>
    <kp value="1000000.0"/>
    <kd value="1.0"/>
  </gazebo>
  
  <!-- Front right leg -->
  <gazebo reference="hip2">
    <mu1>0.85</mu1>
    <mu2>0.85</mu2>
  </gazebo>
  <gazebo reference="upper2">
    <mu1>0.85</mu1>
    <mu2>0.85</mu2>
    <self_collide>0</self_collide>
    <kp value="1000000.0"/>
    <kd value="1.0"/>
  </gazebo>
  <gazebo reference="lower2">
    <mu1>0.85</mu1>
    <mu2>0.85</mu2>
    <self_collide>0</self_collide>
  </gazebo>
  <gazebo reference="toe2">
    <mu1>0.85</mu1>
    <mu2>0.85</mu2>
    <self_collide>0</self_collide>
    <kp value="1000000.0"/>
    <kd value="1.0"/>
  </gazebo>
  
  <!-- Rear right leg -->
  <gazebo reference="hip3">
    <mu1>0.85</mu1>
    <mu2>0.85</mu2>
  </gazebo>
  <gazebo reference="upper3">
    <mu1>0.85</mu1>
    <mu2>0.85</mu2>
    <self_collide>0</self_collide>
    <kp value="1000000.0"/>
    <kd value="1.0"/>
  </gazebo>
  <gazebo reference="lower3">
    <mu1>0.85</mu1>
    <mu2>0.85</mu2>
    <self_collide>0</self_collide>
  </gazebo>
  <gazebo reference="toe3">
    <mu1>0.85</mu1>
    <mu2>0.85</mu2>
    <self_collide>0</self_collide>
    <kp value="1000000.0"/>
    <kd value="1.0"/>
  </gazebo>

  <gazebo reference='jtoe0'>
    <preserveFixedJoint>true</preserveFixedJoint>
  </gazebo>
  <gazebo reference='jtoe1'>
    <preserveFixedJoint>true</preserveFixedJoint>
  </gazebo>
  <gazebo reference='jtoe2'>
    <preserveFixedJoint>true</preserveFixedJoint>
  </gazebo>
  <gazebo reference='jtoe3'>
    <preserveFixedJoint>true</preserveFixedJoint>
  </gazebo>

  <!-- Transmissions -->
  <transmission name="transmission_8">
    <type>transmission_interface/SimpleTransmission</type>
    <joint name="8">
      <hardwareInterface>hardware_interface/EffortJointInterface</hardwareInterface>
    </joint>
    <actuator name="motor_8">
      <hardwareInterface>EffortJointInterface</hardwareInterface>
      <mechanicalReduction>1</mechanicalReduction>
    </actuator>
  </transmission>
  <transmission name="transmission_0">
    <type>transmission_interface/SimpleTransmission</type>
    <joint name="0">
      <hardwareInterface>hardware_interface/EffortJointInterface</hardwareInterface>
    </joint>
    <actuator name="motor_0">
      <hardwareInterface>EffortJointInterface</hardwareInterface>
      <mechanicalReduction>1</mechanicalReduction>
    </actuator>
  </transmission>
  <transmission name="transmission_1">
    <type>transmission_interface/SimpleTransmission</type>
    <joint name="1">
      <hardwareInterface>hardware_interface/EffortJointInterface</hardwareInterface>
    </joint>
    <actuator name="motor_1">
      <hardwareInterface>EffortJointInterface</hardwareInterface>
      <mechanicalReduction>1</mechanicalReduction>
    </actuator>
  </transmission>

  <transmission name="transmission_9">
    <type>transmission_interface/SimpleTransmission</type>
    <joint name="9">
      <hardwareInterface>hardware_interface/EffortJointInterface</hardwareInterface>
    </joint>
    <actuator name="motor_9">
      <hardwareInterface>EffortJointInterface</hardwareInterface>
      <mechanicalReduction>1</mechanicalReduction>
    </actuator>
  </transmission>
  <transmission name="transmission_2">
    <type>transmission_interface/SimpleTransmission</type>
    <joint name="2">
      <hardwareInterface>hardware_interface/EffortJointInterface</hardwareInterface>
    </joint>
    <actuator name="motor_2">
      <hardwareInterface>EffortJointInterface</hardwareInterface>
      <mechanicalReduction>1</mechanicalReduction>
    </actuator>
  </transmission>
  <transmission name="transmission_3">
    <type>transmission_interface/SimpleTransmission</type>
    <joint name="3">
      <hardwareInterface>hardware_interface/EffortJointInterface</hardwareInterface>
    </joint>
    <actuator name="motor_3">
      <hardwareInterface>EffortJointInterface</hardwareInterface>
      <mechanicalReduction>1</mechanicalReduction>
    </actuator>
  </transmission>

  <transmission name="transmission_10">
    <type>transmission_interface/SimpleTransmission</type>
    <joint name="10">
      <hardwareInterface>hardware_interface/EffortJointInterface</hardwareInterface>
    </joint>
    <actuator name="motor_10">
      <hardwareInterface>EffortJointInterface</hardwareInterface>
      <mechanicalReduction>1</mechanicalReduction>
    </actuator>
  </transmission>
  <transmission name="transmission_4">
    <type>transmission_interface/SimpleTransmission</type>
    <joint name="4">
      <hardwareInterface>hardware_interface/EffortJointInterface</hardwareInterface>
    </joint>
    <actuator name="motor_4">
      <hardwareInterface>EffortJointInterface</hardwareInterface>
      <mechanicalReduction>1</mechanicalReduction>
    </actuator>
  </transmission>
  <transmission name="transmission_5">
    <type>transmission_interface/SimpleTransmission</type>
    <joint name="5">
      <hardwareInterface>hardware_interface/EffortJointInterface</hardwareInterface>
    </joint>
    <actuator name="motor_5">
      <hardwareInterface>EffortJointInterface</hardwareInterface>
      <mechanicalReduction>1</mechanicalReduction>
    </actuator>
  </transmission>

  <transmission name="transmission_11">
    <type>transmission_interface/SimpleTransmission</type>
    <joint name="11">
      <hardwareInterface>hardware_interface/EffortJointInterface</hardwareInterface>
    </joint>
    <actuator name="motor_11">
      <hardwareInterface>EffortJointInterface</hardwareInterface>
      <mechanicalReduction>1</mechanicalReduction>
    </actuator>
  </transmission>
  <transmission name="transmission_6">
    <type>transmission_interface/SimpleTransmission</type>
    <joint name="6">
      <hardwareInterface>hardware_interface/EffortJointInterface</hardwareInterface>
    </joint>
    <actuator name="motor_6">
      <hardwareInterface>EffortJointInterface</hardwareInterface>
      <mechanicalReduction>1</mechanicalReduction>
    </actuator>
  </transmission>
  <transmission name="transmission_7">
    <type>transmission_interface/SimpleTransmission</type>
    <joint name="7">
      <hardwareInterface>hardware_interface/EffortJointInterface</hardwareInterface>
    </joint>
    <actuator name="motor_7">
      <hardwareInterface>EffortJointInterface</hardwareInterface>
      <mechanicalReduction>1</mechanicalReduction>
    </actuator>
  </transmission>

  <gazebo reference="camera_link">
    <sensor type="depth" name="realsense_R200">
      <update_rate>5.0</update_rate>
      <always_on>true</always_on>
      <visualize>false</visualize>
      <camera>
          <horizontal_fov>1.0</horizontal_fov>
          <image>
              <width>640</width>
              <height>480</height>
              <format>R8G8B8</format>
          </image>
          <depth_camera></depth_camera>
          <clip>
              <near>0.005</near>
              <far>6</far>
          </clip>
      </camera>
      <plugin name="camera_controller" filename="libgazebo_ros_openni_kinect.so">
        <baseline>0.2</baseline>
        <alwaysOn>true</alwaysOn>
        <updateRate>0.0</updateRate>
        <cameraName>camera</cameraName>
        <frameName>camera_optical</frameName>
        <imageTopicName>rgb/image_raw</imageTopicName>
        <depthImageTopicName>depth/image_raw</depthImageTopicName>
        <pointCloudTopicName>depth/points</pointCloudTopicName>
        <cameraInfoTopicName>rgb/camera_info</cameraInfoTopicName>
        <depthImageCameraInfoTopicName>depth/camera_info</depthImageCameraInfoTopicName>
        <pointCloudCutoff>0.4</pointCloudCutoff>
            <hackBaseline>0.07</hackBaseline>
            <distortionK1>0.0</distortionK1>
            <distortionK2>0.0</distortionK2>
            <distortionK3>0.0</distortionK3>
            <distortionT1>0.0</distortionT1>
            <distortionT2>0.0</distortionT2>
        <CxPrime>0.0</CxPrime>
        <Cx>0.0</Cx>
        <Cy>0.0</Cy>
        <focalLength>0</focalLength>
        <hackBaseline>0</hackBaseline>
      </plugin>
    </sensor>
  </gazebo>
  
</robot>
